Workbook
Name Slicer_Brocker: #N/A
Name Slicer_Broker: #N/A
Name Slicer_Camion: #N/A
Name Slicer_Clientes: #N/A
Name Slicer_Factura1: #N/A
Name Slicer_Fecha1: #N/A
Name Slicer_Proveedor: #N/A
Name Slicer_Proyecto: #N/A
Name Slicer_Proyecto1: #N/A

Sheet Facturas Generales
A1: Fecha | B1: Key_Fact | C1: Factura | D1: Truck | E1: Broker | F1: Observaciones | G1: Camion | H1: Ticket | I1: Clientes | J1: Proyecto | K1: Proyecto OK | L1: Job Ok | M1: Volcadero | N1: TicketVolcadero | O1: Material | P1: Horas o Viaje | Q1: Costo unitario | R1: Total Cobrado | S1: Pago a Broker | T1: Unamed
A2: 13-1-2025 | B2: =tbl_Facturas[[#This Row],[Factura]] & "|" & tbl_Facturas[[#This Row],[Proyecto OK]] & "|" & TEXT(tbl_Facturas[[#This Row],[Horas o Viaje]],"0.00") & "|" & TEXT(tbl_Facturas[[#This Row],[Costo unitario]],"0.00") -> 2328|Lead Service Replacement Project|8.00|115.50 | C2: 2328 | D2: 11 | E2: MLB | G2: 11 | H2: 10818 | I2: Millenium | J2: Lead Service Replacement Project | K2: Lead Service Replacement Project | P2: 8 | Q2: 115.5 | R2: 924 | S2: =IFERROR(_xlfn.XLOOKUP(tbl_Facturas[[#This Row],[Key_Fact]],tbl_Manifiestos[Key_Manif],tbl_Manifiestos[Pagado a Broker],0),0) -> 859.32 | T2: 19.95
A3: 13-1-2025 | B3: =tbl_Facturas[[#This Row],[Factura]] & "|" & tbl_Facturas[[#This Row],[Proyecto OK]] & "|" & TEXT(tbl_Facturas[[#This Row],[Horas o Viaje]],"0.00") & "|" & TEXT(tbl_Facturas[[#This Row],[Costo unitario]],"0.00") -> 2328|Lead Service Replacement Project|8.00|115.50 | C3: 2328 | D3: 308 | E3: AAA | G3: 308 | H3: 11175 | I3: Millenium | J3: Lead Service Replacement Project | K3: Lead Service Replacement Project | P3: 8 | Q3: 115.5 | R3: 924 | S3: =IFERROR(_xlfn.XLOOKUP(tbl_Facturas[[#This Row],[Key_Fact]],tbl_Manifiestos[Key_Manif],tbl_Manifiestos[Pagado a Broker],0),0) -> 859.32 | T3: 943.95
A4: 13-1-2025 | B4: =tbl_Facturas[[#This Row],[Factura]] & "|" & tbl_Facturas[[#This Row],[Proyecto OK]] & "|" & TEXT(tbl_Facturas[[#This Row],[Horas o Viaje]],"0.00") & "|" & TEXT(tbl_Facturas[[#This Row],[Costo unitario]],"0.00") -> 2329|Niles IL|11.00|115.50 | C4: 2329 | D4: 73 | E4: LI | G4: 73 | H4: 11994 | I4: Millenium | J4: Niles IL | K4: Niles IL | M4: Reliable Pulaski | P4: 11 | Q4: 115.5 | R4: 1270.5 | S4: =IFERROR(_xlfn.XLOOKUP(tbl_Facturas[[#This Row],[Key_Fact]],tbl_Manifiestos[Key_Manif],tbl_Manifiestos[Pagado a Broker],0),0) -> 0 | T4: 2214.45
A5: 13-1-2025 | B5: =tbl_Facturas[[#This Row],[Factura]] & "|" & tbl_Facturas[[#This Row],[Proyecto OK]] & "|" & TEXT(tbl_Facturas[[#This Row],[Horas o Viaje]],"0.00") & "|" & TEXT(tbl_Facturas[[#This Row],[Costo unitario]],"0.00") -> 2329|Niles IL|7.00|115.50 | C5: 2329 | D5: 19 | E5: MLB | G5: 19 | H5: 11689 | I5: Millenium | J5: Niles IL | K5: Niles IL | M5: Reliable Lyons | P5: 7 | Q5: 115.5 | R5: 808.5 | S5: =IFERROR(_xlfn.XLOOKUP(tbl_Facturas[[#This Row],[Key_Fact]],tbl_Manifiestos[Key_Manif],tbl_Manifiestos[Pagado a Broker],0),0) -> 751.905 | T5: 3022.95
A6: 13-1-2025 | B6: =tbl_Facturas[[#This Row],[Factura]] & "|" & tbl_Facturas[[#This Row],[Proyecto OK]] & "|" & TEXT(tbl_Facturas[[#This Row],[Horas o Viaje]],"0.00") & "|" & TEXT(tbl_Facturas[[#This Row],[Costo unitario]],"0.00") -> 2330|Lead Replacement Service|9.00|110.00 | C6: 2330 | D6: 67 | E6: LT | G6: 67 | H6: 11612 | I6: PanOceanic | J6: 3347 | K6: Lead Replacement Service | L6: 3347 | P6: 9 | Q6: 110 | R6: 990 | S6: =IFERROR(_xlfn.XLOOKUP(tbl_Facturas[[#This Row],[Key_Fact]],tbl_Manifiestos[Key_Manif],tbl_Manifiestos[Pagado a Broker],0),0) -> 920.7 | T6: 4012.95
A7: 13-1-2025 | B7: =tbl_Facturas[[#This Row],[Factura]] & "|" & tbl_Facturas[[#This Row],[Proyecto OK]] & "|" & TEXT(tbl_Facturas[[#This Row],[Horas o Viaje]],"0.00") & "|" & TEXT(tbl_Facturas[[#This Row],[Costo unitario]],"0.00") -> 2330|Lead Replacement Service|9.00|110.00 | C7: 2330 | D7: 198 | E7: POSADA | G7: 198 | H7: 11426 | I7: PanOceanic | J7: 3347 | K7: Lead Replacement Service | L7: 3347 | P7: 9 | Q7: 110 | R7: 990 | S7: =IFERROR(_xlfn.XLOOKUP(tbl_Facturas[[#This Row],[Key_Fact]],tbl_Manifiestos[Key_Manif],tbl_Manifiestos[Pagado a Broker],0),0) -> 920.7 | T7: 5002.95
A8: 13-1-2025 | B8: =tbl_Facturas[[#This Row],[Factura]] & "|" & tbl_Facturas[[#This Row],[Proyecto OK]] & "|" & TEXT(tbl_Facturas[[#This Row],[Horas o Viaje]],"0.00") & "|" & TEXT(tbl_Facturas[[#This Row],[Costo unitario]],"0.00") -> 2330|Lead Replacement Service|8.50|110.00 | C8: 2330 | D8: 19 | E8: MLB | G8: 19 | H8: 11688 | I8: PanOceanic | J8: 3347 | K8: Lead Replacement Service | L8: 3347 | P8: 8.5 | Q8: 110 | R8: 935 | S8: =IFERROR(_xlfn.XLOOKUP(tbl_Facturas[[#This Row],[Key_Fact]],tbl_Manifiestos[Key_Manif],tbl_Manifiestos[Pagado a Broker],0),0) -> 869.55 | T8: 5937.95
A9: 13-1-2025 | B9: =tbl_Facturas[[#This Row],[Factura]] & "|" & tbl_Facturas[[#This Row],[Proyecto OK]] & "|" & TEXT(tbl_Facturas[[#This Row],[Horas o Viaje]],"0.00") & "|" & TEXT(tbl_Facturas[[#This Row],[Costo unitario]],"0.00") -> 2330|Lead Replacement Service|9.50|110.00 | C9: 2330 | D9: 325 | E9: LT | G9: 325 | H9: 10563 | I9: PanOceanic | J9: 3347 | K9: Lead Replacement Service | L9: 3347 | P9: 9.5 | Q9: 110 | R9: 1045 | S9: =IFERROR(_xlfn.XLOOKUP(tbl_Facturas[[#This Row],[Key_Fact]],tbl_Manifiestos[Key_Manif],tbl_Manifiestos[Pagado a Broker],0),0) -> 971.85 | T9: 6982.95
A10: 13-1-2025 | B10: =tbl_Facturas[[#This Row],[Factura]] & "|" & tbl_Facturas[[#This Row],[Proyecto OK]] & "|" & TEXT(tbl_Facturas[[#This Row],[Horas o Viaje]],"0.00") & "|" & TEXT(tbl_Facturas[[#This Row],[Costo unitario]],"0.00") -> 2330|Lead Replacement Service|10.50|110.00 | C10: 2330 | D10: 617 | E10: LT | G10: 617 | H10: 10564 | I10: PanOceanic | J10: 3347 | K10: Lead Replacement Service | L10: 3347 | P10: 10.5 | Q10: 110 | R10: 1155 | S10: =IFERROR(_xlfn.XLOOKUP(tbl_Facturas[[#This Row],[Key_Fact]],tbl_Manifiestos[Key_Manif],tbl_Manifiestos[Pagado a Broker],0),0) -> 1074.15 | T10: 8137.95
A11: 20-1-2025 | B11: =tbl_Facturas[[#This Row],[Factura]] & "|" & tbl_Facturas[[#This Row],[Proyecto OK]] & "|" & TEXT(tbl_Facturas[[#This Row],[Horas o Viaje]],"0.00") & "|" & TEXT(tbl_Facturas[[#This Row],[Costo unitario]],"0.00") -> 2331|Canal #2 |1.00|199.50 | C11: 2331 | D11: 67 | F11: LT | G11: 67 | H11: 11614 | I11: FHP | J11: Canal #2Job# 6227 | K11: Canal #2 | L11: 6227 | M11: Vulcan Pershing | P11: 1 | Q11: 199.5 | R11: 199.5 | S11: =IFERROR(_xlfn.XLOOKUP(tbl_Facturas[[#This Row],[Key_Fact]],tbl_Manifiestos[Key_Manif],tbl_Manifiestos[Pagado a Broker],0),0) -> 0 | T11: 8337.45
A12: 20-1-2025 | B12: =tbl_Facturas[[#This Row],[Factura]] & "|" & tbl_Facturas[[#This Row],[Proyecto OK]] & "|" & TEXT(tbl_Facturas[[#This Row],[Horas o Viaje]],"0.00") & "|" & TEXT(tbl_Facturas[[#This Row],[Costo unitario]],"0.00") -> 2331|Canal #2 |1.50|132.30 | C12: 2331 | D12: 67 | F12: LT | G12: 67 | H12: 11615 | I12: FHP | J12: Canal #2Job# 6227 | K12: Canal #2 | L12: 6227 | M12: Vulcan Pershing | O12: WAITING TIME | P12: 1.5 | Q12: 132.3 | R12: 198.45 | S12: =IFERROR(_xlfn.XLOOKUP(tbl_Facturas[[#This Row],[Key_Fact]],tbl_Manifiestos[Key_Manif],tbl_Manifiestos[Pagado a Broker],0),0) -> 0 | T12: 8535.9
A13: 20-1-2025 | B13: =tbl_Facturas[[#This Row],[Factura]] & "|" & tbl_Facturas[[#This Row],[Proyecto OK]] & "|" & TEXT(tbl_Facturas[[#This Row],[Horas o Viaje]],"0.00") & "|" & TEXT(tbl_Facturas[[#This Row],[Costo unitario]],"0.00") -> 2331|Canal #2 |1.00|199.50 | C13: 2331 | D13: 67 | F13: LT | G13: 67 | H13: 11616 | I13: FHP | J13: Canal #2Job# 6227 | K13: Canal #2 | L13: 6227 | M13: Vulcan Pershing | P13: 1 | Q13: 199.5 | R13: 199.5 | S13: =IFERROR(_xlfn.XLOOKUP(tbl_Facturas[[#This Row],[Key_Fact]],tbl_Manifiestos[Key_Manif],tbl_Manifiestos[Pagado a Broker],0),0) -> 0 | T13: 8735.4
A14: 20-1-2025 | B14: =tbl_Facturas[[#This Row],[Factura]] & "|" & tbl_Facturas[[#This Row],[Proyecto OK]] & "|" & TEXT(tbl_Facturas[[#This Row],[Horas o Viaje]],"0.00") & "|" & TEXT(tbl_Facturas[[#This Row],[Costo unitario]],"0.00") -> 2331|Canal #2 |1.00|199.50 | C14: 2331 | D14: 67 | F14: LT | G14: 67 | H14: 11617 | I14: FHP | J14: Canal #2Job# 6227 | K14: Canal #2 | L14: 6227 | M14: Vulcan Pershing | P14: 1 | Q14: 199.5 | R14: 199.5 | S14: =IFERROR(_xlfn.XLOOKUP(tbl_Facturas[[#This Row],[Key_Fact]],tbl_Manifiestos[Key_Manif],tbl_Manifiestos[Pagado a Broker],0),0) -> 0 | T14: 8934.9
A15: 20-1-2025 | B15: =tbl_Facturas[[#This Row],[Factura]] & "|" & tbl_Facturas[[#This Row],[Proyecto OK]] & "|" & TEXT(tbl_Facturas[[#This Row],[Horas o Viaje]],"0.00") & "|" & TEXT(tbl_Facturas[[#This Row],[Costo unitario]],"0.00") -> 2331|Canal #2 |1.00|199.50 | C15: 2331 | D15: 67 | F15: LT | G15: 67 | H15: 11618 | I15: FHP | J15: Canal #2Job# 6227 | K15: Canal #2 | L15: 6227 | M15: Vulcan Pershing | P15: 1 | Q15: 199.5 | R15: 199.5 | S15: =IFERROR(_xlfn.XLOOKUP(tbl_Facturas[[#This Row],[Key_Fact]],tbl_Manifiestos[Key_Manif],tbl_Manifiestos[Pagado a Broker],0),0) -> 0 | T15: 9134.4
A16: 20-1-2025 | B16: =tbl_Facturas[[#This Row],[Factura]] & "|" & tbl_Facturas[[#This Row],[Proyecto OK]] & "|" & TEXT(tbl_Facturas[[#This Row],[Horas o Viaje]],"0.00") & "|" & TEXT(tbl_Facturas[[#This Row],[Costo unitario]],"0.00") -> 2331|Canal #2 |1.00|199.50 | C16: 2331 | D16: 67 | F16: LT | G16: 67 | H16: 11622 | I16: FHP | J16: Canal #2Job# 6227 | K16: Canal #2 | L16: 6227 | M16: Vulcan Pershing | P16: 1 | Q16: 199.5 | R16: 199.5 | S16: =IFERROR(_xlfn.XLOOKUP(tbl_Facturas[[#This Row],[Key_Fact]],tbl_Manifiestos[Key_Manif],tbl_Manifiestos[Pagado a Broker],0),0) -> 0 | T16: 9333.9
A17: 20-1-2025 | B17: =tbl_Facturas[[#This Row],[Factura]] & "|" & tbl_Facturas[[#This Row],[Proyecto OK]] & "|" & TEXT(tbl_Facturas[[#This Row],[Horas o Viaje]],"0.00") & "|" & TEXT(tbl_Facturas[[#This Row],[Costo unitario]],"0.00") -> 2331|Canal #2 |1.00|199.50 | C17: 2331 | D17: 19 | F17: MLB | G17: 19 | H17: 11682 | I17: FHP | J17: Canal #2Job# 6227 | K17: Canal #2 | L17: 6227 | M17: Vulcan Pershing | P17: 1 | Q17: 199.5 | R17: 199.5 | S17: =IFERROR(_xlfn.XLOOKUP(tbl_Facturas[[#This Row],[Key_Fact]],tbl_Manifiestos[Key_Manif],tbl_Manifiestos[Pagado a Broker],0),0) -> 0 | T17: 9533.4
A18: 20-1-2025 | B18: =tbl_Facturas[[#This Row],[Factura]] & "|" & tbl_Facturas[[#This Row],[Proyecto OK]] & "|" & TEXT(tbl_Facturas[[#This Row],[Horas o Viaje]],"0.00") & "|" & TEXT(tbl_Facturas[[#This Row],[Costo unitario]],"0.00") -> 2331|Canal #2 |1.00|199.50 | C18: 2331 | D18: 19 | F18: MLB | G18: 19 | H18: 11683 | I18: FHP | J18: Canal #2Job# 6227 | K18: Canal #2 | L18: 6227 | M18: Vulcan Pershing | P18: 1 | Q18: 199.5 | R18: 199.5 | S18: =IFERROR(_xlfn.XLOOKUP(tbl_Facturas[[#This Row],[Key_Fact]],tbl_Manifiestos[Key_Manif],tbl_Manifiestos[Pagado a Broker],0),0) -> 0 | T18: 9732.9
A19: 20-1-2025 | B19: =tbl_Facturas[[#This Row],[Factura]] & "|" & tbl_Facturas[[#This Row],[Proyecto OK]] & "|" & TEXT(tbl_Facturas[[#This Row],[Horas o Viaje]],"0.00") & "|" & TEXT(tbl_Facturas[[#This Row],[Costo unitario]],"0.00") -> 2331|Canal #2 |1.75|132.30 | C19: 2331 | D19: 19 | F19: MLB | G19: 19 | H19: 11684 | I19: FHP | J19: Canal #2Job# 6227 | K19: Canal #2 | L19: 6227 | M19: Vulcan Pershing | O19: WAITING TIME | P19: 1.75 | Q19: 132.3 | R19: 231.53 | S19: =IFERROR(_xlfn.XLOOKUP(tbl_Facturas[[#This Row],[Key_Fact]],tbl_Manifiestos[Key_Manif],tbl_Manifiestos[Pagado a Broker],0),0) -> 0 | T19: 9964.43
A20: 20-1-2025 | B20: =tbl_Facturas[[#This Row],[Factura]] & "|" & tbl_Facturas[[#This Row],[Proyecto OK]] & "|" & TEXT(tbl_Facturas[[#This Row],[Horas o Viaje]],"0.00") & "|" & TEXT(tbl_Facturas[[#This Row],[Costo unitario]],"0.00") -> 2331|Canal #2 |1.00|199.50 | C20: 2331 | D20: 19 | F20: MLB | G20: 19 | H20: 11685 | I20: FHP | J20: Canal #2Job# 6227 | K20: Canal #2 | L20: 6227 | M20: Vulcan Pershing | P20: 1 | Q20: 199.5 | R20: 199.5 | S20: =IFERROR(_xlfn.XLOOKUP(tbl_Facturas[[#This Row],[Key_Fact]],tbl_Manifiestos[Key_Manif],tbl_Manifiestos[Pagado a Broker],0),0) -> 0 | T20: 10163.93
A21: 20-1-2025 | B21: =tbl_Facturas[[#This Row],[Factura]] & "|" & tbl_Facturas[[#This Row],[Proyecto OK]] & "|" & TEXT(tbl_Facturas[[#This Row],[Horas o Viaje]],"0.00") & "|" & TEXT(tbl_Facturas[[#This Row],[Costo unitario]],"0.00") -> 2331|Canal #2 |1.00|199.50 | C21: 2331 | D21: 19 | F21: MLB | G21: 19 | H21: 11686 | I21: FHP | J21: Canal #2Job# 6227 | K21: Canal #2 | L21: 6227 | M21: Vulcan Pershing | P21: 1 | Q21: 199.5 | R21: 199.5 | S21: =IFERROR(_xlfn.XLOOKUP(tbl_Facturas[[#This Row],[Key_Fact]],tbl_Manifiestos[Key_Manif],tbl_Manifiestos[Pagado a Broker],0),0) -> 0 | T21: 10363.43
A22: 20-1-2025 | B22: =tbl_Facturas[[#This Row],[Factura]] & "|" & tbl_Facturas[[#This Row],[Proyecto OK]] & "|" & TEXT(tbl_Facturas[[#This Row],[Horas o Viaje]],"0.00") & "|" & TEXT(tbl_Facturas[[#This Row],[Costo unitario]],"0.00") -> 2331||0.00|0.00 | C22: 2331 | G22: Discount | I22: FHP | R22: -20.54 | S22: =IFERROR(_xlfn.XLOOKUP(tbl_Facturas[[#This Row],[Key_Fact]],tbl_Manifiestos[Key_Manif],tbl_Manifiestos[Pagado a Broker],0),0) -> 0 | T22: 10342.89
A23: 20-1-2025 | B23: =tbl_Facturas[[#This Row],[Factura]] & "|" & tbl_Facturas[[#This Row],[Proyecto OK]] & "|" & TEXT(tbl_Facturas[[#This Row],[Horas o Viaje]],"0.00") & "|" & TEXT(tbl_Facturas[[#This Row],[Costo unitario]],"0.00") -> 2332|Lead Service Replacement Project|7.50|115.50 | C23: 2332 | D23: 198 | E23: POSADA | G23: 198 | H23: 11451 | I23: Millenium | J23: Lead Service Replacement Project | K23: Lead Service Replacement Project | P23: 7.5 | Q23: 115.5 | R23: 866.25 | S23: =IFERROR(_xlfn.XLOOKUP(tbl_Facturas[[#This Row],[Key_Fact]],tbl_Manifiestos[Key_Manif],tbl_Manifiestos[Pagado a Broker],0),0) -> 805.6125 | T23: 11209.14
A24: 20-1-2025 | B24: =tbl_Facturas[[#This Row],[Factura]] & "|" & tbl_Facturas[[#This Row],[Proyecto OK]] & "|" & TEXT(tbl_Facturas[[#This Row],[Horas o Viaje]],"0.00") & "|" & TEXT(tbl_Facturas[[#This Row],[Costo unitario]],"0.00") -> 2332|Lead Service Replacement Project|8.00|115.50 | C24: 2332 | D24: 515 | E24: LT | G24: 515 | H24: 12166 | I24: Millenium | J24: Lead Service Replacement Project | K24: Lead Service Replacement Project | P24: 8 | Q24: 115.5 | R24: 924 | S24: =IFERROR(_xlfn.XLOOKUP(tbl_Facturas[[#This Row],[Key_Fact]],tbl_Manifiestos[Key_Manif],tbl_Manifiestos[Pagado a Broker],0),0) -> 859.32 | T24: 12133.14
A25: 20-1-2025 | B25: =tbl_Facturas[[#This Row],[Factura]] & "|" & tbl_Facturas[[#This Row],[Proyecto OK]] & "|" & TEXT(tbl_Facturas[[#This Row],[Horas o Viaje]],"0.00") & "|" & TEXT(tbl_Facturas[[#This Row],[Costo unitario]],"0.00") -> 2332|Lead Service Replacement Project|8.00|115.50 | C25: 2332 | D25: 11 | E25: MLB | G25: 11 | H25: 11707 | I25: Millenium | J25: Lead Service Replacement Project | K25: Lead Service Replacement Project | P25: 8 | Q25: 115.5 | R25: 924 | S25: =IFERROR(_xlfn.XLOOKUP(tbl_Facturas[[#This Row],[Key_Fact]],tbl_Manifiestos[Key_Manif],tbl_Manifiestos[Pagado a Broker],0),0) -> 859.32 | T25: 13057.14
A26: 20-1-2025 | B26: =tbl_Facturas[[#This Row],[Factura]] & "|" & tbl_Facturas[[#This Row],[Proyecto OK]] & "|" & TEXT(tbl_Facturas[[#This Row],[Horas o Viaje]],"0.00") & "|" & TEXT(tbl_Facturas[[#This Row],[Costo unitario]],"0.00") -> 2332|Lead Service Replacement Project|7.50|115.50 | C26: 2332 | D26: 114 | E26: LT | G26: 114 | H26: 11961 | I26: Millenium | J26: Lead Service Replacement Project | K26: Lead Service Replacement Project | P26: 7.5 | Q26: 115.5 | R26: 866.25 | S26: =IFERROR(_xlfn.XLOOKUP(tbl_Facturas[[#This Row],[Key_Fact]],tbl_Manifiestos[Key_Manif],tbl_Manifiestos[Pagado a Broker],0),0) -> 805.6125 | T26: 13923.39
A27: 20-1-2025 | B27: =tbl_Facturas[[#This Row],[Factura]] & "|" & tbl_Facturas[[#This Row],[Proyecto OK]] & "|" & TEXT(tbl_Facturas[[#This Row],[Horas o Viaje]],"0.00") & "|" & TEXT(tbl_Facturas[[#This Row],[Costo unitario]],"0.00") -> 2333|Lead Replacement Service|10.00|110.00 | C27: 2333 | D27: 67 | E27: LT | G27: 67 | H27: 11613 | I27: PanOceanic | J27: 3347 | K27: Lead Replacement Service | L27: 3347 | P27: 10 | Q27: 110 | R27: 1100 | S27: =IFERROR(_xlfn.XLOOKUP(tbl_Facturas[[#This Row],[Key_Fact]],tbl_Manifiestos[Key_Manif],tbl_Manifiestos[Pagado a Broker],0),0) -> 1023 | T27: 15023.39
A28: 20-1-2025 | B28: =tbl_Facturas[[#This Row],[Factura]] & "|" & tbl_Facturas[[#This Row],[Proyecto OK]] & "|" & TEXT(tbl_Facturas[[#This Row],[Horas o Viaje]],"0.00") & "|" & TEXT(tbl_Facturas[[#This Row],[Costo unitario]],"0.00") -> 2333|Lead Replacement Service|10.00|110.00 | C28: 2333 | D28: 617 | E28: LT | G28: 617 | H28: 10565 | I28: PanOceanic | J28: 3347 | K28: Lead Replacement Service | L28: 3347 | P28: 10 | Q28: 110 | R28: 1100 | S28: =IFERROR(_xlfn.XLOOKUP(tbl_Facturas[[#This Row],[Key_Fact]],tbl_Manifiestos[Key_Manif],tbl_Manifiestos[Pagado a Broker],0),0) -> 1023 | T28: 16123.39
A29: 20-1-2025 | B29: =tbl_Facturas[[#This Row],[Factura]] & "|" & tbl_Facturas[[#This Row],[Proyecto OK]] & "|" & TEXT(tbl_Facturas[[#This Row],[Horas o Viaje]],"0.00") & "|" & TEXT(tbl_Facturas[[#This Row],[Costo unitario]],"0.00") -> 2333|Lead Replacement Service|16.00|110.00 | C29: 2333 | D29: 73 | E29: LI | G29: 73 | H29: 11995 | I29: PanOceanic | J29: 3347 | K29: Lead Replacement Service | L29: 3347 | P29: 16 | Q29: 110 | R29: 1760 | S29: =IFERROR(_xlfn.XLOOKUP(tbl_Facturas[[#This Row],[Key_Fact]],tbl_Manifiestos[Key_Manif],tbl_Manifiestos[Pagado a Broker],0),0) -> 0 | T29: 17883.39
A30: 20-1-2025 | B30: =tbl_Facturas[[#This Row],[Factura]] & "|" & tbl_Facturas[[#This Row],[Proyecto OK]] & "|" & TEXT(tbl_Facturas[[#This Row],[Horas o Viaje]],"0.00") & "|" & TEXT(tbl_Facturas[[#This Row],[Costo unitario]],"0.00") -> 2333|Lead Replacement Service|13.00|110.00 | C30: 2333 | D30: 617 | E30: LT | G30: 617 | H30: 10566 | I30: PanOceanic | J30: 3347 | K30: Lead Replacement Service | L30: 3347 | P30: 13 | Q30: 110 | R30: 1430 | S30: =IFERROR(_xlfn.XLOOKUP(tbl_Facturas[[#This Row],[Key_Fact]],tbl_Manifiestos[Key_Manif],tbl_Manifiestos[Pagado a Broker],0),0) -> 1329.9 | T30: 19313.39
A31: 20-1-2025 | B31: =tbl_Facturas[[#This Row],[Factura]] & "|" & tbl_Facturas[[#This Row],[Proyecto OK]] & "|" & TEXT(tbl_Facturas[[#This Row],[Horas o Viaje]],"0.00") & "|" & TEXT(tbl_Facturas[[#This Row],[Costo unitario]],"0.00") -> 2333|Lead Replacement Service|10.00|110.00 | C31: 2333 | D31: 617 | E31: LT | G31: 617 | H31: 10567 | I31: PanOceanic | J31: 3347 | K31: Lead Replacement Service | L31: 3347 | P31: 10 | Q31: 110 | R31: 1100 | S31: =IFERROR(_xlfn.XLOOKUP(tbl_Facturas[[#This Row],[Key_Fact]],tbl_Manifiestos[Key_Manif],tbl_Manifiestos[Pagado a Broker],0),0) -> 1023 | T31: 20413.39
A32: 20-1-2025 | B32: =tbl_Facturas[[#This Row],[Factura]] & "|" & tbl_Facturas[[#This Row],[Proyecto OK]] & "|" & TEXT(tbl_Facturas[[#This Row],[Horas o Viaje]],"0.00") & "|" & TEXT(tbl_Facturas[[#This Row],[Costo unitario]],"0.00") -> 2334|Lead Service Line Replacements|10.50|115.00 | C32: 2334 | D32: 308 | E32: AAA | G32: 308 | H32: 11108 | I32: Plumbing | J32: Lead Service Line Replacements | K32: Lead Service Line Replacements | P32: 10.5 | Q32: 115 | R32: 1207.5 | S32: =IFERROR(_xlfn.XLOOKUP(tbl_Facturas[[#This Row],[Key_Fact]],tbl_Manifiestos[Key_Manif],tbl_Manifiestos[Pagado a Broker],0),0) -> 1122.975 | T32: 21620.89
A33: 20-1-2025 | B33: =tbl_Facturas[[#This Row],[Factura]] & "|" & tbl_Facturas[[#This Row],[Proyecto OK]] & "|" & TEXT(tbl_Facturas[[#This Row],[Horas o Viaje]],"0.00") & "|" & TEXT(tbl_Facturas[[#This Row],[Costo unitario]],"0.00") -> 2334|Lead Service Line Replacements|9.00|115.00 | C33: 2334 | D33: 198 | E33: POSADA | G33: 198 | H33: 11452 | I33: Plumbing | J33: Lead Service Line Replacements | K33: Lead Service Line Replacements | P33: 9 | Q33: 115 | R33: 1035 | S33: =IFERROR(_xlfn.XLOOKUP(tbl_Facturas[[#This Row],[Key_Fact]],tbl_Manifiestos[Key_Manif],tbl_Manifiestos[Pagado a Broker],0),0) -> 962.55 | T33: 22655.89
A34: 20-1-2025 | B34: =tbl_Facturas[[#This Row],[Factura]] & "|" & tbl_Facturas[[#This Row],[Proyecto OK]] & "|" & TEXT(tbl_Facturas[[#This Row],[Horas o Viaje]],"0.00") & "|" & TEXT(tbl_Facturas[[#This Row],[Costo unitario]],"0.00") -> 2334|Lead Service Line Replacements|8.00|115.00 | C34: 2334 | D34: 19 | E34: MLB | G34: 19 | H34: 11687 | I34: Plumbing | J34: Lead Service Line Replacements | K34: Lead Service Line Replacements | P34: 8 | Q34: 115 | R34: 920 | S34: =IFERROR(_xlfn.XLOOKUP(tbl_Facturas[[#This Row],[Key_Fact]],tbl_Manifiestos[Key_Manif],tbl_Manifiestos[Pagado a Broker],0),0) -> 855.6 | T34: 23575.89
A35: 20-1-2025 | B35: =tbl_Facturas[[#This Row],[Factura]] & "|" & tbl_Facturas[[#This Row],[Proyecto OK]] & "|" & TEXT(tbl_Facturas[[#This Row],[Horas o Viaje]],"0.00") & "|" & TEXT(tbl_Facturas[[#This Row],[Costo unitario]],"0.00") -> 2334|Lead Service Line Replacements|8.00|115.00 | C35: 2334 | D35: 308 | E35: AAA | G35: 308 | H35: 11107 | I35: Plumbing | J35: Lead Service Line Replacements | K35: Lead Service Line Replacements | P35: 8 | Q35: 115 | R35: 920 | S35: =IFERROR(_xlfn.XLOOKUP(tbl_Facturas[[#This Row],[Key_Fact]],tbl_Manifiestos[Key_Manif],tbl_Manifiestos[Pagado a Broker],0),0) -> 855.6 | T35: 24495.89
A36: 20-1-2025 | B36: =tbl_Facturas[[#This Row],[Factura]] & "|" & tbl_Facturas[[#This Row],[Proyecto OK]] & "|" & TEXT(tbl_Facturas[[#This Row],[Horas o Viaje]],"0.00") & "|" & TEXT(tbl_Facturas[[#This Row],[Costo unitario]],"0.00") -> 2334|Lead Service Line Replacements|8.00|115.00 | C36: 2334 | D36: 325 | E36: LT | G36: 325 | H36: 11381 | I36: Plumbing | J36: Lead Service Line Replacements | K36: Lead Service Line Replacements | P36: 8 | Q36: 115 | R36: 920 | S36: =IFERROR(_xlfn.XLOOKUP(tbl_Facturas[[#This Row],[Key_Fact]],tbl_Manifiestos[Key_Manif],tbl_Manifiestos[Pagado a Broker],0),0) -> 855.6 | T36: 25415.89
A37: 20-1-2025 | B37: =tbl_Facturas[[#This Row],[Factura]] & "|" & tbl_Facturas[[#This Row],[Proyecto OK]] & "|" & TEXT(tbl_Facturas[[#This Row],[Horas o Viaje]],"0.00") & "|" & TEXT(tbl_Facturas[[#This Row],[Costo unitario]],"0.00") -> 2334|Lead Service Line Replacements|8.00|115.00 | C37: 2334 | D37: 198 | E37: POSADA | G37: 198 | H37: 11453 | I37: Plumbing | J37: Lead Service Line Replacements | K37: Lead Service Line Replacements | P37: 8 | Q37: 115 | R37: 920 | S37: =IFERROR(_xlfn.XLOOKUP(tbl_Facturas[[#This Row],[Key_Fact]],tbl_Manifiestos[Key_Manif],tbl_Manifiestos[Pagado a Broker],0),0) -> 855.6 | T37: 26335.89
A38: 27-1-2025 | B38: =tbl_Facturas[[#This Row],[Factura]] & "|" & tbl_Facturas[[#This Row],[Proyecto OK]] & "|" & TEXT(tbl_Facturas[[#This Row],[Horas o Viaje]],"0.00") & "|" & TEXT(tbl_Facturas[[#This Row],[Costo unitario]],"0.00") -> 2335|Canal #2 |1.00|199.50 | C38: 2335 | D38: 67 | F38: LT | G38: 67 | H38: 11619 | I38: FHP | J38: Canal #2Job# 6227 | K38: Canal #2 | L38: 6227 | M38: Vulcan Pershing | P38: 1 | Q38: 199.5 | R38: 199.5 | S38: =IFERROR(_xlfn.XLOOKUP(tbl_Facturas[[#This Row],[Key_Fact]],tbl_Manifiestos[Key_Manif],tbl_Manifiestos[Pagado a Broker],0),0) -> 0 | T38: 26535.39
A39: 27-1-2025 | B39: =tbl_Facturas[[#This Row],[Factura]] & "|" & tbl_Facturas[[#This Row],[Proyecto OK]] & "|" & TEXT(tbl_Facturas[[#This Row],[Horas o Viaje]],"0.00") & "|" & TEXT(tbl_Facturas[[#This Row],[Costo unitario]],"0.00") -> 2335|Canal #2 |1.00|199.50 | C39: 2335 | D39: 67 | F39: LT | G39: 67 | H39: 11620 | I39: FHP | J39: Canal #2Job# 6227 | K39: Canal #2 | L39: 6227 | M39: Vulcan Pershing | P39: 1 | Q39: 199.5 | R39: 199.5 | S39: =IFERROR(_xlfn.XLOOKUP(tbl_Facturas[[#This Row],[Key_Fact]],tbl_Manifiestos[Key_Manif],tbl_Manifiestos[Pagado a Broker],0),0) -> 0 | T39: 26734.89
A40: 27-1-2025 | B40: =tbl_Facturas[[#This Row],[Factura]] & "|" & tbl_Facturas[[#This Row],[Proyecto OK]] & "|" & TEXT(tbl_Facturas[[#This Row],[Horas o Viaje]],"0.00") & "|" & TEXT(tbl_Facturas[[#This Row],[Costo unitario]],"0.00") -> 2335|Canal #2 |1.00|199.50 | C40: 2335 | D40: 67 | F40: LT | G40: 67 | H40: 11621 | I40: FHP | J40: Canal #2Job# 6227 | K40: Canal #2 | L40: 6227 | M40: Vulcan Pershing | P40: 1 | Q40: 199.5 | R40: 199.5 | S40: =IFERROR(_xlfn.XLOOKUP(tbl_Facturas[[#This Row],[Key_Fact]],tbl_Manifiestos[Key_Manif],tbl_Manifiestos[Pagado a Broker],0),0) -> 0 | T40: 26934.39
...

Sheet Manifiestos Varios
A1: Proveedor | B1: Key_Manif | C1: Factura | D1: Fecha | E1: Brocker | F1: Customer | G1: Proyecto | H1: Proyecto OK | I1: Job Ok | J1: Servicio | K1: Costo Unitario | L1: Total Pagado | M1: Pagado a Broker | N1: Porcentaje
A2: J&O | B2: =tbl_Manifiestos[[#This Row],[Factura]] & "|" & tbl_Manifiestos[[#This Row],[Proyecto OK]] & "|" & TEXT(tbl_Manifiestos[[#This Row],[Servicio]],"0.00") & "|" & TEXT(tbl_Manifiestos[[#This Row],[Costo Unitario]],"0.00") -> 2768|Metra 115th|5.00|220.00 | C2: 2768 | D2: 45925 | E2: 686 | F2: Viridian | G2: 41 | H2: Metra 115th | J2: 5 | K2: 220 | L2: 1100 | M2: =tbl_Manifiestos[[#This Row],[Total Pagado]]*tbl_Manifiestos[[#This Row],[Porcentaje]] -> 990 | N2: 0.9
A3: MJV | B3: =tbl_Manifiestos[[#This Row],[Factura]] & "|" & tbl_Manifiestos[[#This Row],[Proyecto OK]] & "|" & TEXT(tbl_Manifiestos[[#This Row],[Servicio]],"0.00") & "|" & TEXT(tbl_Manifiestos[[#This Row],[Costo Unitario]],"0.00") -> 2441|F.M.|8.00|100.00 | C3: 2441 | D3: 45778 | E3: MJV-678 | F3: Foundation Mechanics | G3: 52.34 | H3: F.M. | J3: 8 | K3: 100 | L3: 800 | M3: =tbl_Manifiestos[[#This Row],[Total Pagado]]*tbl_Manifiestos[[#This Row],[Porcentaje]] -> 720 | N3: 0.9
A4: XPREZ | B4: =tbl_Manifiestos[[#This Row],[Factura]] & "|" & tbl_Manifiestos[[#This Row],[Proyecto OK]] & "|" & TEXT(tbl_Manifiestos[[#This Row],[Servicio]],"0.00") & "|" & TEXT(tbl_Manifiestos[[#This Row],[Costo Unitario]],"0.00") -> 2441|F.M.|8.00|100.00 | C4: 2441 | D4: 45778 | E4: XPRES-4 | F4: Foundation Mechanics | G4: 55.75 | H4: F.M. | J4: 8 | K4: 100 | L4: 800 | M4: =tbl_Manifiestos[[#This Row],[Total Pagado]]*tbl_Manifiestos[[#This Row],[Porcentaje]] -> 720 | N4: 0.9
A5: MJV | B5: =tbl_Manifiestos[[#This Row],[Factura]] & "|" & tbl_Manifiestos[[#This Row],[Proyecto OK]] & "|" & TEXT(tbl_Manifiestos[[#This Row],[Servicio]],"0.00") & "|" & TEXT(tbl_Manifiestos[[#This Row],[Costo Unitario]],"0.00") -> 2441|F.M.|8.00|100.00 | C5: 2441 | D5: 45770 | E5: MJV-678 | F5: Foundation Mechanics | G5: 73.78 | H5: F.M. | J5: 8 | K5: 100 | L5: 800 | M5: =tbl_Manifiestos[[#This Row],[Total Pagado]]*tbl_Manifiestos[[#This Row],[Porcentaje]] -> 720 | N5: 0.9
A6: XPREZ | B6: =tbl_Manifiestos[[#This Row],[Factura]] & "|" & tbl_Manifiestos[[#This Row],[Proyecto OK]] & "|" & TEXT(tbl_Manifiestos[[#This Row],[Servicio]],"0.00") & "|" & TEXT(tbl_Manifiestos[[#This Row],[Costo Unitario]],"0.00") -> 2441|F.M.|8.00|100.00 | C6: 2441 | D6: 45770 | E6: XPRES-4 | F6: Foundation Mechanics | G6: 82.91 | H6: F.M. | J6: 8 | K6: 100 | L6: 800 | M6: =tbl_Manifiestos[[#This Row],[Total Pagado]]*tbl_Manifiestos[[#This Row],[Porcentaje]] -> 720 | N6: 0.9
A7: CAJETAS | B7: =tbl_Manifiestos[[#This Row],[Factura]] & "|" & tbl_Manifiestos[[#This Row],[Proyecto OK]] & "|" & TEXT(tbl_Manifiestos[[#This Row],[Servicio]],"0.00") & "|" & TEXT(tbl_Manifiestos[[#This Row],[Costo Unitario]],"0.00") -> 2641|CDOT S-403|8.50|105.00 | C7: 2641 | D7: 45870 | E7: 54 | F7: Sumit | G7: 403 | H7: CDOT S-403 | J7: 8.5 | K7: 105 | L7: 892.5 | M7: =tbl_Manifiestos[[#This Row],[Total Pagado]]*tbl_Manifiestos[[#This Row],[Porcentaje]] -> 803.25 | N7: 0.9
A8: BBR | B8: =tbl_Manifiestos[[#This Row],[Factura]] & "|" & tbl_Manifiestos[[#This Row],[Proyecto OK]] & "|" & TEXT(tbl_Manifiestos[[#This Row],[Servicio]],"0.00") & "|" & TEXT(tbl_Manifiestos[[#This Row],[Costo Unitario]],"0.00") -> 2656|CDOT S-403|10.50|105.00 | C8: 2656 | D8: 45874 | E8: 25 | F8: Sumit | G8: 403 | H8: CDOT S-403 | J8: 10.5 | K8: 105 | L8: 1102.5 | M8: =tbl_Manifiestos[[#This Row],[Total Pagado]]*tbl_Manifiestos[[#This Row],[Porcentaje]] -> 992.25 | N8: 0.9
A9: BBR | B9: =tbl_Manifiestos[[#This Row],[Factura]] & "|" & tbl_Manifiestos[[#This Row],[Proyecto OK]] & "|" & TEXT(tbl_Manifiestos[[#This Row],[Servicio]],"0.00") & "|" & TEXT(tbl_Manifiestos[[#This Row],[Costo Unitario]],"0.00") -> 2669|CDOT S-403|9.00|105.00 | C9: 2669 | D9: 45875 | E9: 25 | F9: Sumit | G9: 403 | H9: CDOT S-403 | J9: 9 | K9: 105 | L9: 945 | M9: =tbl_Manifiestos[[#This Row],[Total Pagado]]*tbl_Manifiestos[[#This Row],[Porcentaje]] -> 850.5 | N9: 0.9
A10: BBR | B10: =tbl_Manifiestos[[#This Row],[Factura]] & "|" & tbl_Manifiestos[[#This Row],[Proyecto OK]] & "|" & TEXT(tbl_Manifiestos[[#This Row],[Servicio]],"0.00") & "|" & TEXT(tbl_Manifiestos[[#This Row],[Costo Unitario]],"0.00") -> 2669|CDOT S-403|9.00|105.00 | C10: 2669 | D10: 45876 | E10: 25 | F10: Sumit | G10: 403 | H10: CDOT S-403 | J10: 9 | K10: 105 | L10: 945 | M10: =tbl_Manifiestos[[#This Row],[Total Pagado]]*tbl_Manifiestos[[#This Row],[Porcentaje]] -> 850.5 | N10: 0.9
A11: HERRERA | B11: =tbl_Manifiestos[[#This Row],[Factura]] & "|" & tbl_Manifiestos[[#This Row],[Proyecto OK]] & "|" & TEXT(tbl_Manifiestos[[#This Row],[Servicio]],"0.00") & "|" & TEXT(tbl_Manifiestos[[#This Row],[Costo Unitario]],"0.00") -> 2669|CDOT S-403|8.50|105.00 | C11: 2669 | D11: 45884 | E11: 92 | F11: Sumit | G11: 403 | H11: CDOT S-403 | J11: 8.5 | K11: 105 | L11: 892.5 | M11: =tbl_Manifiestos[[#This Row],[Total Pagado]]*tbl_Manifiestos[[#This Row],[Porcentaje]] -> 803.25 | N11: 0.9
A12: UMBRELLA | B12: =tbl_Manifiestos[[#This Row],[Factura]] & "|" & tbl_Manifiestos[[#This Row],[Proyecto OK]] & "|" & TEXT(tbl_Manifiestos[[#This Row],[Servicio]],"0.00") & "|" & TEXT(tbl_Manifiestos[[#This Row],[Costo Unitario]],"0.00") -> 2656|CDOT S-403|8.00|105.00 | C12: 2656 | D12: 45873 | E12: 661 | F12: Sumit | G12: 403 | H12: CDOT S-403 | J12: 8 | K12: 105 | L12: 840 | M12: =tbl_Manifiestos[[#This Row],[Total Pagado]]*tbl_Manifiestos[[#This Row],[Porcentaje]] -> 756 | N12: 0.9
A13: UMBRELLA | B13: =tbl_Manifiestos[[#This Row],[Factura]] & "|" & tbl_Manifiestos[[#This Row],[Proyecto OK]] & "|" & TEXT(tbl_Manifiestos[[#This Row],[Servicio]],"0.00") & "|" & TEXT(tbl_Manifiestos[[#This Row],[Costo Unitario]],"0.00") -> 2656|CDOT S-403|9.50|105.00 | C13: 2656 | D13: 45874 | E13: 661 | F13: Sumit | G13: 403 | H13: CDOT S-403 | J13: 9.5 | K13: 105 | L13: 997.5 | M13: =tbl_Manifiestos[[#This Row],[Total Pagado]]*tbl_Manifiestos[[#This Row],[Porcentaje]] -> 897.75 | N13: 0.9
A14: UMBRELLA | B14: =tbl_Manifiestos[[#This Row],[Factura]] & "|" & tbl_Manifiestos[[#This Row],[Proyecto OK]] & "|" & TEXT(tbl_Manifiestos[[#This Row],[Servicio]],"0.00") & "|" & TEXT(tbl_Manifiestos[[#This Row],[Costo Unitario]],"0.00") -> 2656|CDOT S-403|9.00|105.00 | C14: 2656 | D14: 45875 | E14: 661 | F14: Sumit | G14: 403 | H14: CDOT S-403 | J14: 9 | K14: 105 | L14: 945 | M14: =tbl_Manifiestos[[#This Row],[Total Pagado]]*tbl_Manifiestos[[#This Row],[Porcentaje]] -> 850.5 | N14: 0.9
A15: UMBRELLA | B15: =tbl_Manifiestos[[#This Row],[Factura]] & "|" & tbl_Manifiestos[[#This Row],[Proyecto OK]] & "|" & TEXT(tbl_Manifiestos[[#This Row],[Servicio]],"0.00") & "|" & TEXT(tbl_Manifiestos[[#This Row],[Costo Unitario]],"0.00") -> 2669|CDOT S-403|8.00|105.00 | C15: 2669 | D15: 45881 | E15: 28 | F15: Sumit | G15: 403 | H15: CDOT S-403 | J15: 8 | K15: 105 | L15: 840 | M15: =tbl_Manifiestos[[#This Row],[Total Pagado]]*tbl_Manifiestos[[#This Row],[Porcentaje]] -> 756 | N15: 0.9
A16: UMBRELLA | B16: =tbl_Manifiestos[[#This Row],[Factura]] & "|" & tbl_Manifiestos[[#This Row],[Proyecto OK]] & "|" & TEXT(tbl_Manifiestos[[#This Row],[Servicio]],"0.00") & "|" & TEXT(tbl_Manifiestos[[#This Row],[Costo Unitario]],"0.00") -> 2669|CDOT S-403|8.00|105.00 | C16: 2669 | D16: 45882 | E16: 28 | F16: Sumit | G16: 403 | H16: CDOT S-403 | J16: 8 | K16: 105 | L16: 840 | M16: =tbl_Manifiestos[[#This Row],[Total Pagado]]*tbl_Manifiestos[[#This Row],[Porcentaje]] -> 756 | N16: 0.9
A17: WO | B17: =tbl_Manifiestos[[#This Row],[Factura]] & "|" & tbl_Manifiestos[[#This Row],[Proyecto OK]] & "|" & TEXT(tbl_Manifiestos[[#This Row],[Servicio]],"0.00") & "|" & TEXT(tbl_Manifiestos[[#This Row],[Costo Unitario]],"0.00") -> 2682|CDOT S-403|9.00|105.00 | C17: 2682 | D17: 45891 | E17: 102 | F17: Sumit | G17: 403 | H17: CDOT S-403 | J17: 9 | K17: 105 | L17: 945 | M17: =tbl_Manifiestos[[#This Row],[Total Pagado]]*tbl_Manifiestos[[#This Row],[Porcentaje]] -> 850.5 | N17: 0.9
A18: CAJETAS | B18: =tbl_Manifiestos[[#This Row],[Factura]] & "|" & tbl_Manifiestos[[#This Row],[Proyecto OK]] & "|" & TEXT(tbl_Manifiestos[[#This Row],[Servicio]],"0.00") & "|" & TEXT(tbl_Manifiestos[[#This Row],[Costo Unitario]],"0.00") -> 2698|CDOT S-403|9.00|105.00 | C18: 2698 | D18: 45896 | E18: 606 | F18: Sumit | G18: 403 | H18: CDOT S-403 | J18: 9 | K18: 105 | L18: 945 | M18: =tbl_Manifiestos[[#This Row],[Total Pagado]]*tbl_Manifiestos[[#This Row],[Porcentaje]] -> 850.5 | N18: 0.9
... A38: WO | B38: =tbl_Manifiestos[[#This Row],[Factura]] & "|" & tbl_Manifiestos[[#This Row],[Proyecto OK]] & "|" & TEXT(tbl_Manifiestos[[#This Row],[Servicio]],"0.00") & "|" & TEXT(tbl_Manifiestos[[#This Row],[Costo Unitario]],"0.00") -> 2910|CDOT S-403|8.00|105.00 | C38: 2910 | D38: 45978 | E38: 7 | F38: Sumit | G38: 403 | H38: CDOT S-403 | J38: 8 | K38: 105 | L38: 840 | M38: =tbl_Manifiestos[[#This Row],[Total Pagado]]*tbl_Manifiestos[[#This Row],[Porcentaje]] -> 756 | N38: 0.9
A39: LT | B39: =tbl_Manifiestos[[#This Row],[Factura]] & "|" & tbl_Manifiestos[[#This Row],[Proyecto OK]] & "|" & TEXT(tbl_Manifiestos[[#This Row],[Servicio]],"0.00") & "|" & TEXT(tbl_Manifiestos[[#This Row],[Costo Unitario]],"0.00") -> 2641|CDOT S-403|9.50|115.00 | C39: 2641 | D39: 45868 | E39: 325 | F39: Sumit | G39: 403 | H39: CDOT S-403 | J39: 9.5 | K39: 115 | L39: =J39*K39 -> 1092.5 | M39: =tbl_Manifiestos[[#This Row],[Total Pagado]]*tbl_Manifiestos[[#This Row],[Porcentaje]] -> 1016.025 | N39: 0.93
A40: LT | B40: =tbl_Manifiestos[[#This Row],[Factura]] & "|" & tbl_Manifiestos[[#This Row],[Proyecto OK]] & "|" & TEXT(tbl_Manifiestos[[#This Row],[Servicio]],"0.00") & "|" & TEXT(tbl_Manifiestos[[#This Row],[Costo Unitario]],"0.00") -> 2641|CDOT S-403|10.00|115.00 | C40: 2641 | D40: 45869 | E40: 325 | F40: Sumit | G40: 403 | H40: CDOT S-403 | J40: 10 | K40: 115 | L40: =J40*K40 -> 1150 | M40: =tbl_Manifiestos[[#This Row],[Total Pagado]]*tbl_Manifiestos[[#This Row],[Porcentaje]] -> 1069.5 | N40: 0.93
A41: LT | B41: =tbl_Manifiestos[[#This Row],[Factura]] & "|" & tbl_Manifiestos[[#This Row],[Proyecto OK]] & "|" & TEXT(tbl_Manifiestos[[#This Row],[Servicio]],"0.00") & "|" & TEXT(tbl_Manifiestos[[#This Row],[Costo Unitario]],"0.00") -> 2641|CDOT S-403|8.50|115.00 | C41: 2641 | D41: 45870 | E41: 325 | F41: Sumit | G41: 403 | H41: CDOT S-403 | J41: 8.5 | K41: 115 | L41: =J41*K41 -> 977.5 | M41: =tbl_Manifiestos[[#This Row],[Total Pagado]]*tbl_Manifiestos[[#This Row],[Porcentaje]] -> 909.075 | N41: 0.93
A42: LT | B42: =tbl_Manifiestos[[#This Row],[Factura]] & "|" & tbl_Manifiestos[[#This Row],[Proyecto OK]] & "|" & TEXT(tbl_Manifiestos[[#This Row],[Servicio]],"0.00") & "|" & TEXT(tbl_Manifiestos[[#This Row],[Costo Unitario]],"0.00") -> 2656|CDOT S-403|9.00|115.00 | C42: 2656 | D42: 45873 | E42: 325 | F42: Sumit | G42: 403 | H42: CDOT S-403 | J42: 9 | K42: 115 | L42: =J42*K42 -> 1035 | M42: =tbl_Manifiestos[[#This Row],[Total Pagado]]*tbl_Manifiestos[[#This Row],[Porcentaje]] -> 962.55 | N42: 0.93
A43: LT | B43: =tbl_Manifiestos[[#This Row],[Factura]] & "|" & tbl_Manifiestos[[#This Row],[Proyecto OK]] & "|" & TEXT(tbl_Manifiestos[[#This Row],[Servicio]],"0.00") & "|" & TEXT(tbl_Manifiestos[[#This Row],[Costo Unitario]],"0.00") -> 2656|CDOT S-403|10.50|115.00 | C43: 2656 | D43: 45875 | E43: 325 | F43: Sumit | G43: 403 | H43: CDOT S-403 | J43: 10.5 | K43: 115 | L43: =J43*K43 -> 1207.5 | M43: =tbl_Manifiestos[[#This Row],[Total Pagado]]*tbl_Manifiestos[[#This Row],[Porcentaje]] -> 1122.975 | N43: 0.93
A44: LT | B44: =tbl_Manifiestos[[#This Row],[Factura]] & "|" & tbl_Manifiestos[[#This Row],[Proyecto OK]] & "|" & TEXT(tbl_Manifiestos[[#This Row],[Servicio]],"0.00") & "|" & TEXT(tbl_Manifiestos[[#This Row],[Costo Unitario]],"0.00") -> 2656|CDOT S-403|9.25|115.00 | C44: 2656 | D44: 45877 | E44: 325 | F44: Sumit | G44: 403 | H44: CDOT S-403 | J44: 9.25 | K44: 115 | L44: =J44*K44 -> 1063.75 | M44: =tbl_Manifiestos[[#This Row],[Total Pagado]]*tbl_Manifiestos[[#This Row],[Porcentaje]] -> 989.2875 | N44: 0.93
A45: LT | B45: =tbl_Manifiestos[[#This Row],[Factura]] & "|" & tbl_Manifiestos[[#This Row],[Proyecto OK]] & "|" & TEXT(tbl_Manifiestos[[#This Row],[Servicio]],"0.00") & "|" & TEXT(tbl_Manifiestos[[#This Row],[Costo Unitario]],"0.00") -> 2656|CDOT S-403|10.50|115.00 | C45: 2656 | D45: 45876 | E45: 325 | F45: Sumit | G45: 403 | H45: CDOT S-403 | J45: 10.5 | K45: 115 | L45: =J45*K45 -> 1207.5 | M45: =tbl_Manifiestos[[#This Row],[Total Pagado]]*tbl_Manifiestos[[#This Row],[Porcentaje]] -> 1122.975 | N45: 0.93
A46: LT | B46: =tbl_Manifiestos[[#This Row],[Factura]] & "|" & tbl_Manifiestos[[#This Row],[Proyecto OK]] & "|" & TEXT(tbl_Manifiestos[[#This Row],[Servicio]],"0.00") & "|" & TEXT(tbl_Manifiestos[[#This Row],[Costo Unitario]],"0.00") -> 2656|CDOT S-403|9.50|115.00 | C46: 2656 | D46: 45874 | E46: 325 | F46: Sumit | G46: 403 | H46: CDOT S-403 | J46: 9.5 | K46: 115 | L46: =J46*K46 -> 1092.5 | M46: =tbl_Manifiestos[[#This Row],[Total Pagado]]*tbl_Manifiestos[[#This Row],[Porcentaje]] -> 1016.025 | N46: 0.93
A47: LT | B47: =tbl_Manifiestos[[#This Row],[Factura]] & "|" & tbl_Manifiestos[[#This Row],[Proyecto OK]] & "|" & TEXT(tbl_Manifiestos[[#This Row],[Servicio]],"0.00") & "|" & TEXT(tbl_Manifiestos[[#This Row],[Costo Unitario]],"0.00") -> 2669|CDOT S-403|10.00|115.00 | C47: 2669 | D47: 45880 | E47: 325 | F47: Sumit | G47: 403 | H47: CDOT S-403 | J47: 10 | K47: 115 | L47: =J47*K47 -> 1150 | M47: =tbl_Manifiestos[[#This Row],[Total Pagado]]*tbl_Manifiestos[[#This Row],[Porcentaje]] -> 1069.5 | N47: 0.93
A48: LT | B48: =tbl_Manifiestos[[#This Row],[Factura]] & "|" & tbl_Manifiestos[[#This Row],[Proyecto OK]] & "|" & TEXT(tbl_Manifiestos[[#This Row],[Servicio]],"0.00") & "|" & TEXT(tbl_Manifiestos[[#This Row],[Costo Unitario]],"0.00") -> 2669|CDOT S-403|8.00|115.00 | C48: 2669 | D48: 45881 | E48: 325 | F48: Sumit | G48: 403 | H48: CDOT S-403 | J48: 8 | K48: 115 | L48: =J48*K48 -> 920 | M48: =tbl_Manifiestos[[#This Row],[Total Pagado]]*tbl_Manifiestos[[#This Row],[Porcentaje]] -> 855.6 | N48: 0.93
A49: LT | B49: =tbl_Manifiestos[[#This Row],[Factura]] & "|" & tbl_Manifiestos[[#This Row],[Proyecto OK]] & "|" & TEXT(tbl_Manifiestos[[#This Row],[Servicio]],"0.00") & "|" & TEXT(tbl_Manifiestos[[#This Row],[Costo Unitario]],"0.00") -> 2669|CDOT S-403|10.00|115.00 | C49: 2669 | D49: 45882 | E49: 325 | F49: Sumit | G49: 403 | H49: CDOT S-403 | J49: 10 | K49: 115 | L49: =J49*K49 -> 1150 | M49: =tbl_Manifiestos[[#This Row],[Total Pagado]]*tbl_Manifiestos[[#This Row],[Porcentaje]] -> 1069.5 | N49: 0.93
A50: LT | B50: =tbl_Manifiestos[[#This Row],[Factura]] & "|" & tbl_Manifiestos[[#This Row],[Proyecto OK]] & "|" & TEXT(tbl_Manifiestos[[#This Row],[Servicio]],"0.00") & "|" & TEXT(tbl_Manifiestos[[#This Row],[Costo Unitario]],"0.00") -> 2669|CDOT S-403|9.00|115.00 | C50: 2669 | D50: 45883 | E50: 325 | F50: Sumit | G50: 403 | H50: CDOT S-403 | J50: 9 | K50: 115 | L50: =J50*K50 -> 1035 | M50: =tbl_Manifiestos[[#This Row],[Total Pagado]]*tbl_Manifiestos[[#This Row],[Porcentaje]] -> 962.55 | N50: 0.93
... A105: MLB | B105: =tbl_Manifiestos[[#This Row],[Factura]] & "|" & tbl_Manifiestos[[#This Row],[Proyecto OK]] & "|" & TEXT(tbl_Manifiestos[[#This Row],[Servicio]],"0.00") & "|" & TEXT(tbl_Manifiestos[[#This Row],[Costo Unitario]],"0.00") -> 2781|CDOT S-403|9.00|115.00 | C105: 2781 | D105: 45931 | E105: 82 | F105: Sumit | G105: 403 | H105: CDOT S-403 | J105: 9 | K105: 115 | L105: =J105*K105 -> 1035 | M105: =tbl_Manifiestos[[#This Row],[Total Pagado]]*tbl_Manifiestos[[#This Row],[Porcentaje]] -> 962.55 | N105: 0.93
A106: MLB | B106: =tbl_Manifiestos[[#This Row],[Factura]] & "|" & tbl_Manifiestos[[#This Row],[Proyecto OK]] & "|" & TEXT(tbl_Manifiestos[[#This Row],[Servicio]],"0.00") & "|" & TEXT(tbl_Manifiestos[[#This Row],[Costo Unitario]],"0.00") -> 2796|CDOT S-403|9.00|115.00 | C106: 2796 | D106: 45936 | E106: 11 | F106: Sumit | G106: 403 | H106: CDOT S-403 | J106: 9 | K106: 115 | L106: 1035 | M106: =tbl_Manifiestos[[#This Row],[Total Pagado]]*tbl_Manifiestos[[#This Row],[Porcentaje]] -> 962.55 | N106: 0.93
A107: MLB | B107: =tbl_Manifiestos[[#This Row],[Factura]] & "|" & tbl_Manifiestos[[#This Row],[Proyecto OK]] & "|" & TEXT(tbl_Manifiestos[[#This Row],[Servicio]],"0.00") & "|" & TEXT(tbl_Manifiestos[[#This Row],[Costo Unitario]],"0.00") -> 2796|CDOT S-403|8.00|115.00 | C107: 2796 | D107: 45938 | E107: 82 | F107: Sumit | G107: 403 | H107: CDOT S-403 | J107: 8 | K107: 115 | L107: 920 | M107: =tbl_Manifiestos[[#This Row],[Total Pagado]]*tbl_Manifiestos[[#This Row],[Porcentaje]] -> 855.6 | N107: 0.93
A108: MLB | B108: =tbl_Manifiestos[[#This Row],[Factura]] & "|" & tbl_Manifiestos[[#This Row],[Proyecto OK]] & "|" & TEXT(tbl_Manifiestos[[#This Row],[Servicio]],"0.00") & "|" & TEXT(tbl_Manifiestos[[#This Row],[Costo Unitario]],"0.00") -> 2796|CDOT S-403|8.00|115.00 | C108: 2796 | D108: 45939 | E108: 82 | F108: Sumit | G108: 403 | H108: CDOT S-403 | J108: 8 | K108: 115 | L108: 920 | M108: =tbl_Manifiestos[[#This Row],[Total Pagado]]*tbl_Manifiestos[[#This Row],[Porcentaje]] -> 855.6 | N108: 0.93
A109: MLB | B109: =tbl_Manifiestos[[#This Row],[Factura]] & "|" & tbl_Manifiestos[[#This Row],[Proyecto OK]] & "|" & TEXT(tbl_Manifiestos[[#This Row],[Servicio]],"0.00") & "|" & TEXT(tbl_Manifiestos[[#This Row],[Costo Unitario]],"0.00") -> 2796|CDOT S-403|8.00|115.00 | C109: 2796 | D109: 45940 | E109: 82 | F109: Sumit | G109: 403 | H109: CDOT S-403 | J109: 8 | K109: 115 | L109: 920 | M109: =tbl_Manifiestos[[#This Row],[Total Pagado]]*tbl_Manifiestos[[#This Row],[Porcentaje]] -> 855.6 | N109: 0.93
A110: MLB | B110: =tbl_Manifiestos[[#This Row],[Factura]] & "|" & tbl_Manifiestos[[#This Row],[Proyecto OK]] & "|" & TEXT(tbl_Manifiestos[[#This Row],[Servicio]],"0.00") & "|" & TEXT(tbl_Manifiestos[[#This Row],[Costo Unitario]],"0.00") -> 2811|CDOT S-403|8.00|115.00 | C110: 2811 | D110: 45943 | E110: 82 | F110: Sumit | G110: 403 | H110: CDOT S-403 | J110: 8 | K110: 115 | L110: =J110*K110 -> 920 | M110: =tbl_Manifiestos[[#This Row],[Total Pagado]]*tbl_Manifiestos[[#This Row],[Porcentaje]] -> 855.6 | N110: 0.93
A111: MLB | B111: =tbl_Manifiestos[[#This Row],[Factura]] & "|" & tbl_Manifiestos[[#This Row],[Proyecto OK]] & "|" & TEXT(tbl_Manifiestos[[#This Row],[Servicio]],"0.00") & "|" & TEXT(tbl_Manifiestos[[#This Row],[Costo Unitario]],"0.00") -> 2811|CDOT S-403|9.00|115.00 | C111: 2811 | D111: 45944 | E111: 82 | F111: Sumit | G111: 403 | H111: CDOT S-403 | J111: 9 | K111: 115 | L111: =J111*K111 -> 1035 | M111: =tbl_Manifiestos[[#This Row],[Total Pagado]]*tbl_Manifiestos[[#This Row],[Porcentaje]] -> 962.55 | N111: 0.93
A112: MLB | B112: =tbl_Manifiestos[[#This Row],[Factura]] & "|" & tbl_Manifiestos[[#This Row],[Proyecto OK]] & "|" & TEXT(tbl_Manifiestos[[#This Row],[Servicio]],"0.00") & "|" & TEXT(tbl_Manifiestos[[#This Row],[Costo Unitario]],"0.00") -> 2811|CDOT S-403|9.00|115.00 | C112: 2811 | D112: 45945 | E112: 82 | F112: Sumit | G112: 403 | H112: CDOT S-403 | J112: 9 | K112: 115 | L112: =J112*K112 -> 1035 | M112: =tbl_Manifiestos[[#This Row],[Total Pagado]]*tbl_Manifiestos[[#This Row],[Porcentaje]] -> 962.55 | N112: 0.93
A113: MLB | B113: =tbl_Manifiestos[[#This Row],[Factura]] & "|" & tbl_Manifiestos[[#This Row],[Proyecto OK]] & "|" & TEXT(tbl_Manifiestos[[#This Row],[Servicio]],"0.00") & "|" & TEXT(tbl_Manifiestos[[#This Row],[Costo Unitario]],"0.00") -> 2811|CDOT S-403|9.00|115.00 | C113: 2811 | D113: 45946 | E113: 82 | F113: Sumit | G113: 403 | H113: CDOT S-403 | J113: 9 | K113: 115 | L113: =J113*K113 -> 1035 | M113: =tbl_Manifiestos[[#This Row],[Total Pagado]]*tbl_Manifiestos[[#This Row],[Porcentaje]] -> 962.55 | N113: 0.93
...

Sheet Dashboard
A2: Año | B2: (Todas)
A3: Mes | B3: 01
A5: Etiquetas de fila | B5: Total Cobrado a Cliente | C5: Pago Total a Broker
A6: Total general

Sheet Manifiestos Dashboard
A1: DASHBOARD
B19: Pago por cliente por periodo
B20: Fecha / Cliente | C20: Costo Unitario Total | D20: Total Pagado | E20: 90% Total
B21: 41 | C21: 220 | D21: 1100 | E21: 990
B22: 2025 | C22: 220 | D22: 1100 | E22: 990
B23: Qtr3 | C23: 220 | D23: 1100 | E23: 990
B24: Sep | C24: 220 | D24: 1100 | E24: 990
B25: 45925 | C25: 220 | D25: 1100 | E25: 990
B26: Viridian | C26: 220 | D26: 1100 | E26: 990
B27: 52.34 | C27: 100 | D27: 800 | E27: 720
B28: 55.75 | C28: 100 | D28: 800 | E28: 720
B29: 2025 | C29: 100 | D29: 800 | E29: 720
B30: Qtr2 | C30: 100 | D30: 800 | E30: 720
B31: May | C31: 100 | D31: 800 | E31: 720
B32: 45778 | C32: 100 | D32: 800 | E32: 720
B33: Foundation Mechanics | C33: 100 | D33: 800 | E33: 720
B34: 73.78 | C34: 100 | D34: 800 | E34: 720
B35: 2025 | C35: 100 | D35: 800 | E35: 720
B36: Qtr2 | C36: 100 | D36: 800 | E36: 720
B37: Apr | C37: 100 | D37: 800 | E37: 720
B38: 45770 | C38: 100 | D38: 800 | E38: 720
B39: Foundation Mechanics | C39: 100 | D39: 800 | E39: 720
B40: 82.91 | C40: 100 | D40: 800 | E40: 720
B41: 2025 | C41: 100 | D41: 800 | E41: 720
B42: Qtr2 | C42: 100 | D42: 800 | E42: 720
B43: Apr | C43: 100 | D43: 800 | E43: 720
B44: 45770 | C44: 100 | D44: 800 | E44: 720
B45: Foundation Mechanics | C45: 100 | D45: 800 | E45: 720
B46: 403 | C46: 3360 | D46: 28691.25 | E46: 25822.14
B47: 2025 | C47: 3360 | D47: 28691.25 | E47: 25822.14
B48: Qtr3 | C48: 2625 | D48: 22732.5 | E48: 20459.26
B49: Aug | C49: 1680 | D49: 14673.75 | E49: 13206.38
B50: 45870 | C50: 105 | D50: 892.5 | E50: 803.25
B51: Sumit | C51: 105 | D51: 892.5 | E51: 803.25
B52: 45873 | C52: 105 | D52: 840 | E52: 756
B53: Sumit | C53: 105 | D53: 840 | E53: 756
B54: 45874 | C54: 210 | D54: 2100 | E54: 1890
B55: Sumit | C55: 210 | D55: 2100 | E55: 1890
B56: 45875 | C56: 210 | D56: 1890 | E56: 1701
B57: Sumit | C57: 210 | D57: 1890 | E57: 1701
...

Sheet Totales
C3: Por Factura | D3: 2313
C4: Cobrado Total | D4: =SUMIF(tbl_Facturas[Factura],Totales!D3,tbl_Facturas[Total Cobrado]) -> 0
C5: Ofrecido a Broker | D5: =SUMIF(tbl_Manifiestos[Factura],Totales!D3,tbl_Manifiestos[Total Pagado]) -> 1000
C6: Pagado a Broker | D6: =SUMIF(tbl_Manifiestos[Factura],Totales!D3,tbl_Manifiestos[Pagado a Broker]) -> 906
C9: Por Mes
C10: Por Cliente | D10: PanOceanic
C11: Cobrado Total | D11: =SUMIF(tbl_Facturas[Factura],Totales!D10,tbl_Facturas[Total Cobrado]) -> 0
C12: Ofrecido a Broker | D12: =SUMIF(tbl_Manifiestos[Customer],Totales!D10,tbl_Manifiestos[Total Pagado]) -> 611943.25
C13: Pagado a Broker | D13: =SUMIF(tbl_Manifiestos[Customer],Totales!D10,tbl_Manifiestos[Pagado a Broker]) -> 567126.45
C15: Por Año | D15: 2025
C16: Por Mes | D16: 08
C17: Por Proyecto
C18: Cobrado Total | D18: =SUMIFS( tbl_Facturas[Total Cobrado], tbl_Facturas[Proyecto], IF(D17="", "*", D17), #REF!, IF(D16="", "*", D16), #REF!, IF(D15="", "*", D15) ) -> #REF!
C19: Ofrecido a Broker | D19: =SUMIFS( tbl_Manifiestos[Total Pagado], tbl_Manifiestos[Proyecto], IF(D17="", "*", D17), #REF!, IF(D16="", "*", D16), #REF!, IF(D15="", "*", D15) ) -> #REF!
C20: Pagado a Broker | D20: =SUMIFS( tbl_Manifiestos[Pagado a Broker], tbl_Manifiestos[Proyecto], IF(D17="", "*", D17), #REF!, IF(D16="", "*", D16), #REF!, IF(D15="", "*", D15) ) -> #REF!
